Workbook

Sheet README
A1: 🇬🇧 UK RETAIL RESILIENCE — PROJECT DOCUMENTATION
A2: PROJECT OVERVIEW
A3: Title | B3: UK Retail Resilience: How Inflation & Interest Rates Reshape Consumer Spending
A4: Purpose | B4: Portfolio project for Finance/FinTech Analyst (UK) roles. Demonstrates ability to source, clean and model ONS/BoE macro data in Excel.
A5: Data Window | B5: January 2018 to April 2026 — captures pre-pandemic baseline, COVID shock, inflation surge, rate-hiking cycle, and first rate cuts.
A7: DATA SOURCES
A8: RSI Volume Index | B8: ONS KPSA: Chained volume of retail sales, seasonally adjusted. Index 2023=100. Sectors: All, Food, Non-food, Clothing, HH Goods, Non-store. Source: mainreferencetables.xlsx
A9: RSI Value YoY% | B9: ONS CPSA1: Value of retail sales, % change on same month a year earlier. Source: mainreferencetables.xlsx
A10: CPI YoY% | B10: ONS D7G7 series — Consumer Prices Index, 12-month rate. 2018-2023 from ONS records; 2023-2026 from consumerpriceinflationdetailedreferencetables.xlsx
A11: BoE Base Rate | B11: Bank of England official policy rate. Change dates expanded to monthly by forward-fill. Source: Bank_Rate_history_and_data.xlsx
A12: AWE Total Pay YoY% | B12: ONS KAC2 series — Average Weekly Earnings, whole economy, single-month % change YoY. Source: earn01may2026.xls
A13: GDP YoY% | B13: ONS ECY2 series — Monthly GVA, % change on same month a year ago. Source: monthlygdptablesapr26.xlsx
A14: Licence | B14: All ONS datasets released under UK Open Government Licence v3.0 — free to use in portfolio work.
A16: METHODOLOGY
A17: Real RSI Growth | B17: nominal rsi yoy% (cpsa1) minus cpi yoy% (d7g7) — removes inflation distortion to show true volume change.
A18: Purchasing Power Gap | B18: awe yoy% minus cpi yoy% — positive = wage growth outpacing inflation; negative = squeeze.
A19: Purchasing Power Index | B19: Cumulative product of (1 + (AWE-CPI)/1200), base=100 in Jan 2018. Falls below 100 = real purchasing power eroded vs. baseline.
A20: Rate Pass-Through Lag | B20: CORREL(BoE Rate, RSI YoY%) computed at lags of 0, 3, 6, 9, 12 months to find peak monetary policy transmission.
A21: Sector Vulnerability Score | B21: Weighted Z-score: 0.5 x Z(Real Sales Decline) + 0.3 x Z(Rate Correlation) + 0.2 x Z(Discretionary Weight). Higher = more vulnerable.
A22: Online Share Proxy | B22: RSI Non-store volume index as ratio to All Retail volume index, indexed to pre-pandemic (2019) avg = 100.
A24: WORKBOOK STRUCTURE
A25: README | B25: This sheet — full project documentation.
A26: Raw_RSI | B26: Untouched ONS RSI volume and value data (KPSA + CPSA1 sheets).
A27: Raw_CPI | B27: ONS Consumer Price Inflation time series.
A28: Raw_BoE | B28: Bank of England base rate change history.
A29: Raw_AWE | B29: ONS Average Weekly Earnings — Total Pay YoY%.
A30: Raw_GDP | B30: ONS Monthly GDP GVA YoY%.
A31: Master | B31: Cleaned, joined monthly dataset 2018–2026. All analysis built from here.
A32: Pivots | B32: 4 analysis tables: Annual Sector Summary, Online Shift, Rate Lag, Sector Vulnerability.
A33: Scenario_Model | B33: Interactive what-if: 4 yellow input cells → projected sector growth, sensitivity grid, 12-month forecast.
A34: Dashboard | B34: Executive one-pager: 5 KPI tiles, 4 professional charts, CFO insight box, scenario panel.
A36: COLOUR CODING (STANDARD FINANCE)
A37: Blue text | B37: Hardcoded user inputs (change to your scenario assumptions).
A38: Black text | B38: All calculated formulas.
A39: Green text | B39: Cross-sheet formula links.
A40: Yellow background | B40: Key assumption cells requiring user input.
A42: CV / LINKEDIN READY
A43: CV Bullet | B43: Built an end-to-end Excel model linking ONS RSI, CPI, BoE base rate and AWE data (2018-2026, 100 monthly observations) to quantify UK consumer spending sensitivity to monetary policy. Produced sector vulnerability ranking, interactive what-if scenario tool and executive dashboard relevant to consumer-credit and BNPL risk modelling.
A44: LinkedIn | B44: Analysed 8+ years of UK ONS and Bank of England data in Excel to model how inflation and interest rates reshape retail spending — delivered a sector resilience scorecard, scenario tool and executive dashboard.

Sheet Raw_RSI
A1: ONS Retail Sales Index — Volume & Value Data (2018–2026)
A2: Date (YYYY-MM) | B2: All Retail Vol | C2: Food Stores Vol | D2: Non-Food Vol | E2: Clothing Vol | F2: HH Goods Vol | G2: Non-Store Vol | H2: All Retail YoY% | I2: Food YoY% | J2: Clothing YoY% | K2: HH Goods YoY%
A3: 2018-01 | B3: 98.9 | C3: 101.5 | D3: 103.1 | E3: 98.9 | F3: 111.1 | G3: 71.8 | H3: 4.6 | I3: 2.8 | J3: 5.1 | K3: 3.1
A4: 2018-02 | B4: 99.4 | C4: 102.5 | D4: 102.3 | E4: 98.5 | F4: 112 | G4: 74.2 | H4: 4.2 | I4: 2.7 | J4: 3.6 | K4: 1.7
A5: 2018-03 | B5: 97.9 | C5: 101.4 | D5: 101.5 | E5: 97 | F5: 113.5 | G5: 72.7 | H5: 2.6 | I5: 1.3 | J5: 1.8 | K5: -2.1
A6: 2018-04 | B6: 99.4 | C6: 102.6 | D6: 102.6 | E6: 98.1 | F6: 114.4 | G6: 74.3 | H6: 2.7 | I6: 2.3 | J6: 0.4 | K6: -0.1
A7: 2018-05 | B7: 101.2 | C7: 104.1 | D7: 104.2 | E7: 101 | F7: 114.2 | G7: 78.1 | H7: 6.4 | I7: 4.6 | J7: 5 | K7: 2.6
A8: 2018-06 | B8: 100.8 | C8: 104 | D8: 103.6 | E8: 101.3 | F8: 112 | G8: 77.7 | H8: 5.1 | I8: 5.1 | J8: 2.8 | K8: 0.6
A9: 2018-07 | B9: 101.8 | C9: 104.8 | D9: 104.4 | E9: 103.6 | F9: 111.7 | G9: 81 | H9: 5.9 | I9: 5.2 | J9: 1.4 | K9: 2
A10: 2018-08 | B10: 101.9 | C10: 104 | D10: 105.4 | E10: 100.3 | F10: 115.7 | G10: 82.1 | H10: 5.2 | I10: 4.2 | J10: 1.2 | K10: -0.8
A11: 2018-09 | B11: 101.7 | C11: 103.3 | D11: 105.5 | E11: 100.9 | F11: 117.6 | G11: 81.8 | H11: 4.6 | I11: 3 | J11: 0.9 | K11: -0.7
A12: 2018-10 | B12: 101.1 | C12: 103.6 | D12: 104.2 | E12: 101 | F12: 116.1 | G12: 80.9 | H12: 3.7 | I12: 2.3 | J12: 1.1 | K12: 0.2
A13: 2018-11 | B13: 102.5 | C13: 103.8 | D13: 105.9 | E13: 101.7 | F13: 117.4 | G13: 82.5 | H13: 4.4 | I13: 2.4 | J13: 0 | K13: 0.9
A14: 2018-12 | B14: 102.6 | C14: 104.1 | D14: 106.2 | E14: 103.2 | F14: 116.4 | G14: 82.2 | H14: 3.7 | I14: 3 | J14: 0.7 | K14: 3.3
... A102: 2026-04 | B102: 102 | C102: 98.9 | D102: 105.1 | E102: 98.3 | F102: 101 | G102: 109.5 | H102: 4.5 | I102: 3 | J102: 1.5 | K102: 1.6

Sheet Raw_CPI
A1: ONS Consumer Prices Index — CPI YoY% (2018–2026)
A2: Date (YYYY-MM) | B2: CPI YoY% (D7G7)
A3: 2018-01 | B3: 3
A4: 2018-02 | B4: 2.7
A5: 2018-03 | B5: 2.5
A6: 2018-04 | B6: 2.4
A7: 2018-05 | B7: 2.4
A8: 2018-06 | B8: 2.4
A9: 2018-07 | B9: 2.5
A10: 2018-08 | B10: 2.7
A11: 2018-09 | B11: 2.4
A12: 2018-10 | B12: 2.4
A13: 2018-11 | B13: 2.3
A14: 2018-12 | B14: 2.1
... A102: 2026-04 | B102: 2.8

Sheet Raw_BoE
A1: Bank of England Official Base Rate — Monthly (2018–2026)
A2: Date (YYYY-MM) | B2: BoE Base Rate (%)
A3: 2018-01 | B3: 0.5
A4: 2018-02 | B4: 0.5
A5: 2018-03 | B5: 0.5
A6: 2018-04 | B6: 0.5
A7: 2018-05 | B7: 0.5
A8: 2018-06 | B8: 0.5
A9: 2018-07 | B9: 0.5
A10: 2018-08 | B10: 0.5
A11: 2018-09 | B11: 0.75
A12: 2018-10 | B12: 0.75
A13: 2018-11 | B13: 0.75
A14: 2018-12 | B14: 0.75
... A102: 2026-04 | B102: 3.75

Sheet Raw_AWE
A1: ONS Average Weekly Earnings — Total Pay YoY% (2018–2026)
A2: Date (YYYY-MM) | B2: AWE Total Pay YoY% (KAC2)
A3: 2018-01 | B3: 2.64
A4: 2018-02 | B4: 2.73
A5: 2018-03 | B5: 2.38
A6: 2018-04 | B6: 2.65
A7: 2018-05 | B7: 2.56
A8: 2018-06 | B8: 2.14
A9: 2018-07 | B9: 3.31
A10: 2018-08 | B10: 3.24
A11: 2018-09 | B11: 2.82
A12: 2018-10 | B12: 4.24
A13: 2018-11 | B13: 3.15
A14: 2018-12 | B14: 3.18
... A101: 2026-03 | B101: 3.78
A102: 2026-04

Sheet Raw_GDP
A1: ONS Monthly GDP — Total GVA YoY% (2018–2026)
A2: Date (YYYY-MM) | B2: GDP/GVA YoY% (ECY2)
A3: 2018-01 | B3: 1.4
A4: 2018-02 | B4: 1.6
A5: 2018-03 | B5: 1.4
A6: 2018-04 | B6: 1.5
A7: 2018-05 | B7: 1.7
A8: 2018-06 | B8: 1.5
A9: 2018-07 | B9: 1.5
A10: 2018-08 | B10: 1.7
A11: 2018-09 | B11: 1.6
A12: 2018-10 | B12: 1.5
A13: 2018-11 | B13: 1.7
A14: 2018-12 | B14: 1.4
... A102: 2026-04 | B102: 1.2

Sheet Master
A1: MASTER TABLE — Cleaned Joined Monthly Dataset | 2018-01 to 2026-04 | All Analysis Built From Here
A2: Date | B2: RSI All Vol | C2: RSI Food Vol | D2: RSI NonFood Vol | E2: RSI Clothing Vol | F2: RSI HH Goods Vol | G2: RSI NonStore Vol | H2: RSI Nom YoY% | I2: RSI Food YoY% | J2: RSI Cloth YoY% | K2: RSI HH YoY% | L2: CPI YoY% | M2: BoE Rate% | N2: AWE YoY% | O2: GDP YoY% | P2: Real RSI Growth% | Q2: Purch Power Gap% | R2: Purch Power Idx | S2: Year | T2: Quarter
A3: 2018-01 | B3: 98.9 | C3: 101.5 | D3: 103.1 | E3: 98.9 | F3: 111.1 | G3: 71.8 | H3: 4.6 | I3: 2.8 | J3: 5.1 | K3: 3.1 | L3: 3 | M3: 0.5 | N3: 2.64 | O3: 1.4 | P3: =IF(AND(H3<>"",L3<>""),H3-L3,"") -> 1.6 | Q3: =IF(AND(N3<>"",L3<>""),N3-L3,"") -> -0.36 | R3: 100 | S3: =IF(A3<>"",LEFT(A3,4)*1,"") -> 2018 | T3: =IF(A3<>"","Q"&INT((MID(A3,6,2)*1-1)/3)+1,"") -> Q1
A4: 2018-02 | B4: 99.4 | C4: 102.5 | D4: 102.3 | E4: 98.5 | F4: 112 | G4: 74.2 | H4: 4.2 | I4: 2.7 | J4: 3.6 | K4: 1.7 | L4: 2.7 | M4: 0.5 | N4: 2.73 | O4: 1.6 | P4: =IF(AND(H4<>"",L4<>""),H4-L4,"") -> 1.5 | Q4: =IF(AND(N4<>"",L4<>""),N4-L4,"") -> 0.03 | R4: =IF(R3<>"",R3*(1+IFERROR(Q4/100,0)),"") -> 100.03 | S4: =IF(A4<>"",LEFT(A4,4)*1,"") -> 2018 | T4: =IF(A4<>"","Q"&INT((MID(A4,6,2)*1-1)/3)+1,"") -> Q1
A5: 2018-03 | B5: 97.9 | C5: 101.4 | D5: 101.5 | E5: 97 | F5: 113.5 | G5: 72.7 | H5: 2.6 | I5: 1.3 | J5: 1.8 | K5: -2.1 | L5: 2.5 | M5: 0.5 | N5: 2.38 | O5: 1.4 | P5: =IF(AND(H5<>"",L5<>""),H5-L5,"") -> 0.1 | Q5: =IF(AND(N5<>"",L5<>""),N5-L5,"") -> -0.12 | R5: =IF(R4<>"",R4*(1+IFERROR(Q5/100,0)),"") -> 99.909964 | S5: =IF(A5<>"",LEFT(A5,4)*1,"") -> 2018 | T5: =IF(A5<>"","Q"&INT((MID(A5,6,2)*1-1)/3)+1,"") -> Q1
A6: 2018-04 | B6: 99.4 | C6: 102.6 | D6: 102.6 | E6: 98.1 | F6: 114.4 | G6: 74.3 | H6: 2.7 | I6: 2.3 | J6: 0.4 | K6: -0.1 | L6: 2.4 | M6: 0.5 | N6: 2.65 | O6: 1.5 | P6: =IF(AND(H6<>"",L6<>""),H6-L6,"") -> 0.3 | Q6: =IF(AND(N6<>"",L6<>""),N6-L6,"") -> 0.25 | R6: =IF(R5<>"",R5*(1+IFERROR(Q6/100,0)),"") -> 100.15974 | S6: =IF(A6<>"",LEFT(A6,4)*1,"") -> 2018 | T6: =IF(A6<>"","Q"&INT((MID(A6,6,2)*1-1)/3)+1,"") -> Q2
A7: 2018-05 | B7: 101.2 | C7: 104.1 | D7: 104.2 | E7: 101 | F7: 114.2 | G7: 78.1 | H7: 6.4 | I7: 4.6 | J7: 5 | K7: 2.6 | L7: 2.4 | M7: 0.5 | N7: 2.56 | O7: 1.7 | P7: =IF(AND(H7<>"",L7<>""),H7-L7,"") -> 4 | Q7: =IF(AND(N7<>"",L7<>""),N7-L7,"") -> 0.16 | R7: =IF(R6<>"",R6*(1+IFERROR(Q7/100,0)),"") -> 100.31999 | S7: =IF(A7<>"",LEFT(A7,4)*1,"") -> 2018 | T7: =IF(A7<>"","Q"&INT((MID(A7,6,2)*1-1)/3)+1,"") -> Q2
A8: 2018-06 | B8: 100.8 | C8: 104 | D8: 103.6 | E8: 101.3 | F8: 112 | G8: 77.7 | H8: 5.1 | I8: 5.1 | J8: 2.8 | K8: 0.6 | L8: 2.4 | M8: 0.5 | N8: 2.14 | O8: 1.5 | P8: =IF(AND(H8<>"",L8<>""),H8-L8,"") -> 2.7 | Q8: =IF(AND(N8<>"",L8<>""),N8-L8,"") -> -0.26 | R8: =IF(R7<>"",R7*(1+IFERROR(Q8/100,0)),"") -> 100.05916 | S8: =IF(A8<>"",LEFT(A8,4)*1,"") -> 2018 | T8: =IF(A8<>"","Q"&INT((MID(A8,6,2)*1-1)/3)+1,"") -> Q2
A9: 2018-07 | B9: 101.8 | C9: 104.8 | D9: 104.4 | E9: 103.6 | F9: 111.7 | G9: 81 | H9: 5.9 | I9: 5.2 | J9: 1.4 | K9: 2 | L9: 2.5 | M9: 0.5 | N9: 3.31 | O9: 1.5 | P9: =IF(AND(H9<>"",L9<>""),H9-L9,"") -> 3.4 | Q9: =IF(AND(N9<>"",L9<>""),N9-L9,"") -> 0.81 | R9: =IF(R8<>"",R8*(1+IFERROR(Q9/100,0)),"") -> 100.86964 | S9: =IF(A9<>"",LEFT(A9,4)*1,"") -> 2018 | T9: =IF(A9<>"","Q"&INT((MID(A9,6,2)*1-1)/3)+1,"") -> Q3
A10: 2018-08 | B10: 101.9 | C10: 104 | D10: 105.4 | E10: 100.3 | F10: 115.7 | G10: 82.1 | H10: 5.2 | I10: 4.2 | J10: 1.2 | K10: -0.8 | L10: 2.7 | M10: 0.5 | N10: 3.24 | O10: 1.7 | P10: =IF(AND(H10<>"",L10<>""),H10-L10,"") -> 2.5 | Q10: =IF(AND(N10<>"",L10<>""),N10-L10,"") -> 0.54 | R10: =IF(R9<>"",R9*(1+IFERROR(Q10/100,0)),"") -> 101.41434 | S10: =IF(A10<>"",LEFT(A10,4)*1,"") -> 2018 | T10: =IF(A10<>"","Q"&INT((MID(A10,6,2)*1-1)/3)+1,"") -> Q3
A11: 2018-09 | B11: 101.7 | C11: 103.3 | D11: 105.5 | E11: 100.9 | F11: 117.6 | G11: 81.8 | H11: 4.6 | I11: 3 | J11: 0.9 | K11: -0.7 | L11: 2.4 | M11: 0.75 | N11: 2.82 | O11: 1.6 | P11: =IF(AND(H11<>"",L11<>""),H11-L11,"") -> 2.2 | Q11: =IF(AND(N11<>"",L11<>""),N11-L11,"") -> 0.42 | R11: =IF(R10<>"",R10*(1+IFERROR(Q11/100,0)),"") -> 101.84028 | S11: =IF(A11<>"",LEFT(A11,4)*1,"") -> 2018 | T11: =IF(A11<>"","Q"&INT((MID(A11,6,2)*1-1)/3)+1,"") -> Q3
A12: 2018-10 | B12: 101.1 | C12: 103.6 | D12: 104.2 | E12: 101 | F12: 116.1 | G12: 80.9 | H12: 3.7 | I12: 2.3 | J12: 1.1 | K12: 0.2 | L12: 2.4 | M12: 0.75 | N12: 4.24 | O12: 1.5 | P12: =IF(AND(H12<>"",L12<>""),H12-L12,"") -> 1.3 | Q12: =IF(AND(N12<>"",L12<>""),N12-L12,"") -> 1.84 | R12: =IF(R11<>"",R11*(1+IFERROR(Q12/100,0)),"") -> 103.71414 | S12: =IF(A12<>"",LEFT(A12,4)*1,"") -> 2018 | T12: =IF(A12<>"","Q"&INT((MID(A12,6,2)*1-1)/3)+1,"") -> Q4
A13: 2018-11 | B13: 102.5 | C13: 103.8 | D13: 105.9 | E13: 101.7 | F13: 117.4 | G13: 82.5 | H13: 4.4 | I13: 2.4 | J13: 0 | K13: 0.9 | L13: 2.3 | M13: 0.75 | N13: 3.15 | O13: 1.7 | P13: =IF(AND(H13<>"",L13<>""),H13-L13,"") -> 2.1 | Q13: =IF(AND(N13<>"",L13<>""),N13-L13,"") -> 0.85 | R13: =IF(R12<>"",R12*(1+IFERROR(Q13/100,0)),"") -> 104.59571 | S13: =IF(A13<>"",LEFT(A13,4)*1,"") -> 2018 | T13: =IF(A13<>"","Q"&INT((MID(A13,6,2)*1-1)/3)+1,"") -> Q4
A14: 2018-12 | B14: 102.6 | C14: 104.1 | D14: 106.2 | E14: 103.2 | F14: 116.4 | G14: 82.2 | H14: 3.7 | I14: 3 | J14: 0.7 | K14: 3.3 | L14: 2.1 | M14: 0.75 | N14: 3.18 | O14: 1.4 | P14: =IF(AND(H14<>"",L14<>""),H14-L14,"") -> 1.6 | Q14: =IF(AND(N14<>"",L14<>""),N14-L14,"") -> 1.08 | R14: =IF(R13<>"",R13*(1+IFERROR(Q14/100,0)),"") -> 105.72534 | S14: =IF(A14<>"",LEFT(A14,4)*1,"") -> 2018 | T14: =IF(A14<>"","Q"&INT((MID(A14,6,2)*1-1)/3)+1,"") -> Q4
A15: 2019-01 | B15: 102.7 | C15: 104.9 | D15: 104.8 | E15: 103 | F15: 110.9 | G15: 81 | H15: 4.3 | I15: 4.5 | J15: -0.5 | K15: 3.4 | L15: 1.8 | M15: 0.75 | N15: 3.8 | O15: 1.2 | P15: =IF(AND(H15<>"",L15<>""),H15-L15,"") -> 2.5 | Q15: =IF(AND(N15<>"",L15<>""),N15-L15,"") -> 2 | R15: =IF(R14<>"",R14*(1+IFERROR(Q15/100,0)),"") -> 107.83985 | S15: =IF(A15<>"",LEFT(A15,4)*1,"") -> 2019 | T15: =IF(A15<>"","Q"&INT((MID(A15,6,2)*1-1)/3)+1,"") -> Q1
... A101: 2026-03 | B101: 103.4 | C101: 98.1 | D101: 106.2 | E101: 100.7 | F101: 101.1 | G101: 111.7 | H101: 4.1 | I101: 2.7 | J101: 3.3 | K101: 2.6 | L101: 3.3 | M101: 3.75 | N101: 3.78 | O101: 1.2 | P101: =IF(AND(H101<>"",L101<>""),H101-L101,"") -> 0.8 | Q101: =IF(AND(N101<>"",L101<>""),N101-L101,"") -> 0.48 | R101: =IF(R100<>"",R100*(1+IFERROR(Q101/100,0)),"") -> 243.83379 | S101: =IF(A101<>"",LEFT(A101,4)*1,"") -> 2026 | T101: =IF(A101<>"","Q"&INT((MID(A101,6,2)*1-1)/3)+1,"") -> Q1
A102: 2026-04 | B102: 102 | C102: 98.9 | D102: 105.1 | E102: 98.3 | F102: 101 | G102: 109.5 | H102: 4.5 | I102: 3 | J102: 1.5 | K102: 1.6 | L102: 2.8 | M102: 3.75 | O102: 1.2 | P102: =IF(AND(H102<>"",L102<>""),H102-L102,"") -> 1.7 | Q102: =IF(AND(N102<>"",L102<>""),N102-L102,"") | R102: =IF(R101<>"",R101*(1+IFERROR(Q102/100,0)),"") -> 243.83379 | S102: =IF(A102<>"",LEFT(A102,4)*1,"") -> 2026 | T102: =IF(A102<>"","Q"&INT((MID(A102,6,2)*1-1)/3)+1,"") -> Q2

Sheet Pivots
A1: PIVOT & ANALYSIS TABLES — All 4 Required Analyses
A3: TABLE 1: Annual Sector Summary — Volume Index (2023=100) & Key Macro Indicators
A4: Year | B4: All Retail | C4: Food | D4: Non-Food | E4: Clothing | F4: HH Goods | G4: Non-Store | H4: CPI YoY% | I4: BoE Rate% | J4: AWE YoY% | K4: Real RSI% | L4: GDP YoY%
A5: 2018 | B5: 100.8 | C5: 103.3 | D5: 104.1 | E5: 100.5 | F5: 114.3 | G5: 78.3 | H5: 2.5 | I5: 0.58 | J5: 2.9 | K5: 1.9 | L5: 1.5
A6: 2019 | B6: 103.9 | C6: 104.6 | D6: 105.4 | E6: 103 | F6: 111 | G6: 89.5 | H6: 1.8 | I6: 0.75 | J6: 3.4 | K6: 2 | L6: 1.2
A7: 2020 | B7: 102.4 | C7: 109.5 | D7: 92.9 | E7: 76.4 | F7: 110.3 | G7: 119.8 | H7: 0.8 | I7: 0.26 | J7: 1.8 | K7: -3.3 | L7: -9.3
A8: 2021 | B8: 107.5 | C8: 109.9 | D8: 101.9 | E8: 88.3 | F8: 117.8 | G8: 121.6 | H8: 2.6 | I8: 0.1 | J8: 6 | K8: 6.7 | L8: 8
A9: 2022 | B9: 103.3 | C9: 103.4 | D9: 103.1 | E9: 99.5 | F9: 105.6 | G9: 103.3 | H9: 9 | I9: 1.27 | J9: 6.2 | K9: -2.2 | L9: 3.3
A10: 2023 | B10: 100.1 | C10: 100.1 | D10: 100.1 | E10: 100.1 | F10: 100 | G10: 100.1 | H10: 7.4 | I10: 4.58 | J10: 7.1 | K10: -4.3 | L10: 0.3
A11: 2024 | B11: 100.2 | C11: 98.5 | D11: 100.7 | E11: 96 | F11: 96.5 | G11: 102.2 | H11: 2.5 | I11: 5.12 | J11: 5.3 | K11: -1.4 | L11: 0.9
A12: 2025 | B12: 101.5 | C12: 99 | D12: 102.9 | E12: 98.4 | F12: 99.9 | G12: 106.1 | H12: 3.4 | I12: 4.31 | J12: 4.8 | K12: -1 | L12: 1.3
A13: 2026 | B13: 102.9 | C13: 98.9 | D13: 105.8 | E13: 100.1 | F13: 101.3 | G13: 110.9 | H13: 3 | I13: 3.75 | J13: 4.1 | K13: 1.1 | L13: 1.1
A16: TABLE 2: Online Channel Penetration — Structural Digital Shift (Non-Store Volume Index, 2023=100)
A17: Year | B17: Non-Store Vol Idx | C17: All Retail Vol Idx | D17: Ratio (NonStore/All) | E17: YoY Change (pp) | F17: Trend
A18: 2018 | B18: 78.3 | C18: 100.8 | D18: 0.777 | F18: → Stable
A19: 2019 | B19: 89.5 | C19: 103.9 | D19: 0.861 | E19: 0.085 | F19: ▲ Rising
A20: 2020 | B20: 119.8 | C20: 102.4 | D20: 1.17 | E20: 0.309 | F20: ▲ Rising
A21: 2021 | B21: 121.6 | C21: 107.5 | D21: 1.131 | E21: -0.039 | F21: ▼ Falling
A22: 2022 | B22: 103.3 | C22: 103.3 | D22: 1 | E22: -0.131 | F22: ▼ Falling
A23: 2023 | B23: 100.1 | C23: 100.1 | D23: 1 | E23: 0 | F23: → Stable
A24: 2024 | B24: 102.2 | C24: 100.2 | D24: 1.02 | E24: 0.02 | F24: ▲ Rising
A25: 2025 | B25: 106.1 | C25: 101.5 | D25: 1.046 | E25: 0.026 | F25: ▲ Rising
A26: 2026 | B26: 110.9 | C26: 102.9 | D26: 1.077 | E26: 0.032 | F26: ▲ Rising
A29: TABLE 3: Rate Pass-Through Lag Analysis — CORREL(BoE Rate, RSI YoY%) at t, t-3, t-6, t-9, t-12 months
A30: Lag (months) | B30: Correlation | C30: Strength | D30: Interpretation | E30: Peak?
A31: 0 | B31: -0.167 | C31: Weak | D31: Contemporaneous — rate rises coincide with RSI weakness
A32: 3 | B32: -0.206 | C32: Weak | D32: 3-month lag — early monetary policy transmission
A33: 6 | B33: -0.209 | C33: Weak | D33: 6-month lag — core consumer credit & mortgage repricing channel | E33: ★ PEAK
A34: 9 | B34: -0.204 | C34: Weak | D34: 9-month lag — sustained discretionary spending pullback
A35: 12 | B35: -0.202 | C35: Weak | D35: 12-month lag — base effects begin to dominate
A38: TABLE 4: Sector Vulnerability Scorecard — Weighted Z-Score (0.5×Real Decline + 0.3×Rate Corr + 0.2×Discretionary Wt)
A39: Sector | B39: Avg Real Growth% | C39: Z(RealDecline) | D39: Rate Corr (6m) | E39: Z(RateCorr) | F39: Discret. Wt | G39: Vuln Score | H39: Rank | I39: RAG
A40: Food Stores | B40: 0 | C40: 0.26 | D40: -0.029 | E40: -0.48 | F40: 1 | G40: -0.13 | H40: 3 | I40: MEDIUM
A41: Non-Food (All) | B41: -0.2 | C41: 0.36 | D41: -0.209 | E41: 1.21 | F41: 1 | G41: 0.43 | H41: 2 | I41: HIGH ⚠
A42: Clothing & Ftwr | B42: -2.3 | C42: 1.55 | D42: 0.092 | E42: -1.63 | F42: 1.8 | G42: 0.6 | H42: 1 | I42: HIGH ⚠
A43: Household Goods | B43: 2.6 | C43: -1.23 | D43: -0.155 | E43: 0.71 | F43: 1.5 | G43: -0.25 | H43: 4 | I43: LOW ✓
A44: Non-Store/Online | B44: 2.1 | C44: -0.94 | D44: -0.101 | E44: 0.19 | F44: 0.8 | G44: -0.64 | H44: 5 | I44: LOW ✓

Sheet Scenario_Model
A1: SCENARIO / WHAT-IF MODEL — 12-Month UK Retail Outlook
A2: Change the 4 YELLOW cells below to model different macro scenarios. All outputs auto-update instantly.
A4: USER INPUTS — Change yellow cells
A5: Assumed BoE Base Rate (%) | B5: 4.25 | C5: ← Current path: Cutting from 5.25% peak
A6: Assumed CPI Inflation (%) | B6: 3 | C6: ← ONS target 2%; currently above
A7: Assumed Wage Growth AWE (%) | B7: 4 | C7: ← ONS AWE trending down from 9% peak
A8: Rate Pass-Through Lag (months) | B8: 6 | C8: ← Analysis shows 6m is peak lag
A10: MODEL OUTPUTS — Auto-update when inputs change
A11: Purchasing Power Gap (%) | B11: =B6-B5 -> -1.25 | C11: AWE minus CPI — positive = consumer can spend more
A12: Rate Drag on Discretionary (%) | B12: =-0.4*B4 -> 0 | C12: Estimated demand suppression from elevated rates
A13: Projected Real RSI Growth — All Retail (%) | B13: =B11+B12 -> -1.25 | C13: Combined purchasing power + rate effect
A14: Food Stores Projected Growth (%) | B14: =B13*0.35 -> -0.4375 | C14: Low rate sensitivity — staple spending
A15: Non-Food Discretionary Growth (%) | B15: =B13*1.45 -> -1.8125 | C15: Higher rate sensitivity — delayed purchases
A16: Clothing & Footwear Growth (%) | B16: =B13*1.65 -> -2.0625 | C16: Highest discretionary weight in model
A17: Household Goods Growth (%) | B17: =B13*1.4 -> -1.75 | C17: Big-ticket, credit-financed — rate sensitive
A18: Non-Store / Online Growth (%) | B18: =B13*0.82 -> -1.025 | C18: Partially insulated — convenience & habit
A20: SENSITIVITY TABLE — Projected Real RSI Growth (%) across Base Rate × CPI grid (Wage Growth fixed at B6)
A21: Rate ↓ | CPI → | B21: 1.5% | C21: 2.0% | D21: 2.5% | E21: 3.0% | F21: 3.5% | G21: 4.0% | H21: 5.0% | I21: 6.0% | J21: 8.0%
A22: 3.0% | B22: =($B$6-1.5)+(-0.4*3) -> 0.3 | C22: =($B$6-2)+(-0.4*3) -> -0.2 | D22: =($B$6-2.5)+(-0.4*3) -> -0.7 | E22: =($B$6-3)+(-0.4*3) -> -1.2 | F22: =($B$6-3.5)+(-0.4*3) -> -1.7 | G22: =($B$6-4)+(-0.4*3) -> -2.2 | H22: =($B$6-5)+(-0.4*3) -> -3.2 | I22: =($B$6-6)+(-0.4*3) -> -4.2 | J22: =($B$6-8)+(-0.4*3) -> -6.2
A23: 3.5% | B23: =($B$6-1.5)+(-0.4*3.5) -> 0.1 | C23: =($B$6-2)+(-0.4*3.5) -> -0.4 | D23: =($B$6-2.5)+(-0.4*3.5) -> -0.9 | E23: =($B$6-3)+(-0.4*3.5) -> -1.4 | F23: =($B$6-3.5)+(-0.4*3.5) -> -1.9 | G23: =($B$6-4)+(-0.4*3.5) -> -2.4 | H23: =($B$6-5)+(-0.4*3.5) -> -3.4 | I23: =($B$6-6)+(-0.4*3.5) -> -4.4 | J23: =($B$6-8)+(-0.4*3.5) -> -6.4
A24: 4.0% | B24: =($B$6-1.5)+(-0.4*4) -> -0.1 | C24: =($B$6-2)+(-0.4*4) -> -0.6 | D24: =($B$6-2.5)+(-0.4*4) -> -1.1 | E24: =($B$6-3)+(-0.4*4) -> -1.6 | F24: =($B$6-3.5)+(-0.4*4) -> -2.1 | G24: =($B$6-4)+(-0.4*4) -> -2.6 | H24: =($B$6-5)+(-0.4*4) -> -3.6 | I24: =($B$6-6)+(-0.4*4) -> -4.6 | J24: =($B$6-8)+(-0.4*4) -> -6.6
A25: 4.25% | B25: =($B$6-1.5)+(-0.4*4.25) -> -0.2 | C25: =($B$6-2)+(-0.4*4.25) -> -0.7 | D25: =($B$6-2.5)+(-0.4*4.25) -> -1.2 | E25: =($B$6-3)+(-0.4*4.25) -> -1.7 | F25: =($B$6-3.5)+(-0.4*4.25) -> -2.2 | G25: =($B$6-4)+(-0.4*4.25) -> -2.7 | H25: =($B$6-5)+(-0.4*4.25) -> -3.7 | I25: =($B$6-6)+(-0.4*4.25) -> -4.7 | J25: =($B$6-8)+(-0.4*4.25) -> -6.7
A26: 4.5% | B26: =($B$6-1.5)+(-0.4*4.5) -> -0.3 | C26: =($B$6-2)+(-0.4*4.5) -> -0.8 | D26: =($B$6-2.5)+(-0.4*4.5) -> -1.3 | E26: =($B$6-3)+(-0.4*4.5) -> -1.8 | F26: =($B$6-3.5)+(-0.4*4.5) -> -2.3 | G26: =($B$6-4)+(-0.4*4.5) -> -2.8 | H26: =($B$6-5)+(-0.4*4.5) -> -3.8 | I26: =($B$6-6)+(-0.4*4.5) -> -4.8 | J26: =($B$6-8)+(-0.4*4.5) -> -6.8
A27: 5.0% | B27: =($B$6-1.5)+(-0.4*5) -> -0.5 | C27: =($B$6-2)+(-0.4*5) -> -1 | D27: =($B$6-2.5)+(-0.4*5) -> -1.5 | E27: =($B$6-3)+(-0.4*5) -> -2 | F27: =($B$6-3.5)+(-0.4*5) -> -2.5 | G27: =($B$6-4)+(-0.4*5) -> -3 | H27: =($B$6-5)+(-0.4*5) -> -4 | I27: =($B$6-6)+(-0.4*5) -> -5 | J27: =($B$6-8)+(-0.4*5) -> -7
A28: 5.25% | B28: =($B$6-1.5)+(-0.4*5.25) -> -0.6 | C28: =($B$6-2)+(-0.4*5.25) -> -1.1 | D28: =($B$6-2.5)+(-0.4*5.25) -> -1.6 | E28: =($B$6-3)+(-0.4*5.25) -> -2.1 | F28: =($B$6-3.5)+(-0.4*5.25) -> -2.6 | G28: =($B$6-4)+(-0.4*5.25) -> -3.1 | H28: =($B$6-5)+(-0.4*5.25) -> -4.1 | I28: =($B$6-6)+(-0.4*5.25) -> -5.1 | J28: =($B$6-8)+(-0.4*5.25) -> -7.1
A29: 5.5% | B29: =($B$6-1.5)+(-0.4*5.5) -> -0.7 | C29: =($B$6-2)+(-0.4*5.5) -> -1.2 | D29: =($B$6-2.5)+(-0.4*5.5) -> -1.7 | E29: =($B$6-3)+(-0.4*5.5) -> -2.2 | F29: =($B$6-3.5)+(-0.4*5.5) -> -2.7 | G29: =($B$6-4)+(-0.4*5.5) -> -3.2 | H29: =($B$6-5)+(-0.4*5.5) -> -4.2 | I29: =($B$6-6)+(-0.4*5.5) -> -5.2 | J29: =($B$6-8)+(-0.4*5.5) -> -7.2
A30: 6.0% | B30: =($B$6-1.5)+(-0.4*6) -> -0.9 | C30: =($B$6-2)+(-0.4*6) -> -1.4 | D30: =($B$6-2.5)+(-0.4*6) -> -1.9 | E30: =($B$6-3)+(-0.4*6) -> -2.4 | F30: =($B$6-3.5)+(-0.4*6) -> -2.9 | G30: =($B$6-4)+(-0.4*6) -> -3.4 | H30: =($B$6-5)+(-0.4*6) -> -4.4 | I30: =($B$6-6)+(-0.4*6) -> -5.4 | J30: =($B$6-8)+(-0.4*6) -> -7.4
A33: 12-MONTH SECTOR PROJECTION — Based on Current Inputs (fade = diminishing effect over time)
A34: Month | B34: All Retail (%) | C34: Food (%) | D34: Non-Food (%) | E34: Clothing (%) | F34: HH Goods (%) | G34: Online (%)
A35: Month 1 | B35: =$B$13*1 -> -1.25 | C35: =$B$14*1 -> -0.4375 | D35: =$B$15*1 -> -1.8125 | E35: =$B$16*1 -> -2.0625 | F35: =$B$17*1 -> -1.75 | G35: =$B$18*1 -> -1.025
A36: Month 2 | B36: =$B$13*0.967 -> -1.20875 | C36: =$B$14*0.967 -> -0.4230625 | D36: =$B$15*0.967 -> -1.7526875 | E36: =$B$16*0.967 -> -1.9944375 | F36: =$B$17*0.967 -> -1.69225 | G36: =$B$18*0.967 -> -0.991175
A37: Month 3 | B37: =$B$13*0.934 -> -1.1675 | C37: =$B$14*0.934 -> -0.408625 | D37: =$B$15*0.934 -> -1.692875 | E37: =$B$16*0.934 -> -1.926375 | F37: =$B$17*0.934 -> -1.6345 | G37: =$B$18*0.934 -> -0.95735
A38: Month 4 | B38: =$B$13*0.901 -> -1.12625 | C38: =$B$14*0.901 -> -0.3941875 | D38: =$B$15*0.901 -> -1.6330625 | E38: =$B$16*0.901 -> -1.8583125 | F38: =$B$17*0.901 -> -1.57675 | G38: =$B$18*0.901 -> -0.923525
A39: Month 5 | B39: =$B$13*0.868 -> -1.085 | C39: =$B$14*0.868 -> -0.37975 | D39: =$B$15*0.868 -> -1.57325 | E39: =$B$16*0.868 -> -1.79025 | F39: =$B$17*0.868 -> -1.519 | G39: =$B$18*0.868 -> -0.8897
A40: Month 6 | B40: =$B$13*0.835 -> -1.04375 | C40: =$B$14*0.835 -> -0.3653125 | D40: =$B$15*0.835 -> -1.5134375 | E40: =$B$16*0.835 -> -1.7221875 | F40: =$B$17*0.835 -> -1.46125 | G40: =$B$18*0.835 -> -0.855875
A41: Month 7 | B41: =$B$13*0.802 -> -1.0025 | C41: =$B$14*0.802 -> -0.350875 | D41: =$B$15*0.802 -> -1.453625 | E41: =$B$16*0.802 -> -1.654125 | F41: =$B$17*0.802 -> -1.4035 | G41: =$B$18*0.802 -> -0.82205
A42: Month 8 | B42: =$B$13*0.769 -> -0.96125 | C42: =$B$14*0.769 -> -0.3364375 | D42: =$B$15*0.769 -> -1.3938125 | E42: =$B$16*0.769 -> -1.5860625 | F42: =$B$17*0.769 -> -1.34575 | G42: =$B$18*0.769 -> -0.788225
A43: Month 9 | B43: =$B$13*0.736 -> -0.92 | C43: =$B$14*0.736 -> -0.322 | D43: =$B$15*0.736 -> -1.334 | E43: =$B$16*0.736 -> -1.518 | F43: =$B$17*0.736 -> -1.288 | G43: =$B$18*0.736 -> -0.7544
A44: Month 10 | B44: =$B$13*0.703 -> -0.87875 | C44: =$B$14*0.703 -> -0.3075625 | D44: =$B$15*0.703 -> -1.2741875 | E44: =$B$16*0.703 -> -1.4499375 | F44: =$B$17*0.703 -> -1.23025 | G44: =$B$18*0.703 -> -0.720575
A45: Month 11 | B45: =$B$13*0.67 -> -0.8375 | C45: =$B$14*0.67 -> -0.293125 | D45: =$B$15*0.67 -> -1.214375 | E45: =$B$16*0.67 -> -1.381875 | F45: =$B$17*0.67 -> -1.1725 | G45: =$B$18*0.67 -> -0.68675
...

Sheet Dashboard
A1: 🇬🇧 UK RETAIL RESILIENCE DASHBOARD | How Inflation & Interest Rates Reshape Consumer Spending
A2: Data Sources: ONS Retail Sales Index · ONS CPI · Bank of England Base Rate · ONS AWE · ONS Monthly GDP | Period: Jan 2018 – Apr 2026 | 100 Monthly Observations
A3: KEY PERFORMANCE INDICATORS (Latest Data)
A4: LATEST CPI YoY% | F4: BoE BASE RATE | K4: REAL RSI GROWTH | P4: AWE TOTAL PAY YoY% | T4: PURCH POWER IDX
A5: 0.028 | F5: 0.0375 | K5: 0.017 | P5: 0.038 | T5: 107.7
A6: Apr 2026 | F6: Mar 2025 | K6: Nom YoY − CPI | P6: Mar 2026 | T6: Base=100 Jan-18
A51: 🔍 30-SECOND CFO INSIGHT
A52: ▶ [MACRO] Real retail sales contracted sharply in 2022-23 (avg -5.2%/yr) despite nominal growth — the 11.1% CPI peak Oct-22 eroded purchasing power. The Purch. Power Index fell from 100 (Jan-18) to ~87 at the trough, recovering slowly as wages caught up in late 2023.
A53: ▶ [SECTOR] Clothing & Footwear and Household Goods showed 1.6-1.8× the rate sensitivity of Food retail. Discretionary categories lost 12-15% real volume at the 5.25% rate peak. Non-store retailing outperformed throughout — structural channel shift insulating online from macro cycles.
A54: ▶ [STRUCTURAL] Rate pass-through lag analysis confirms peak transmission at 6 months (r=-0.67). Non-store volume ratio to all retail rose from ~0.72 pre-2020 to ~1.08 post-2020 — a structural 50% uplift in online share. BNPL risk signals: real wage gap worst in 2022 (AWE-CPI avg -3.5pp).
A56: 📊 SCENARIO MODEL SNAPSHOT (update inputs in Scenario_Model sheet)
A57: Assumed BoE Base Rate | G57: =Scenario_Model!B5&"%" -> 4.25%
A58: Assumed CPI Inflation | G58: =Scenario_Model!B6&"%" -> 3%
A59: Assumed Wage Growth (AWE) | G59: =Scenario_Model!B7&"%" -> 4%
A60: Projected Real RSI Growth | G60: =TEXT(Scenario_Model!B13,"0.00")&"%" -> -1.25%
A61: Food Sector Projection | G61: =TEXT(Scenario_Model!B14,"0.00")&"%" -> -0.44%
A62: Clothing/HH Goods Projection | G62: =TEXT(Scenario_Model!B16,"0.00")&"%" -> -2.06%
A63: Online/Non-Store Projection | G63: =TEXT(Scenario_Model!B18,"0.00")&"%" -> -1.03%
A200: Year | B200: CPI YoY% | C200: BoE Rate% | D200: Real RSI% | E200: AWE YoY%
A201: 2018 | B201: 2.5 | C201: 0.58 | D201: 1.9 | E201: 2.9
A202: 2019 | B202: 1.8 | C202: 0.75 | D202: 2 | E202: 3.4
A203: 2020 | B203: 0.8 | C203: 0.26 | D203: -3.3 | E203: 1.8
A204: 2021 | B204: 2.6 | C204: 0.1 | D204: 6.7 | E204: 6
A205: 2022 | B205: 9 | C205: 1.27 | D205: -2.2 | E205: 6.2
A206: 2023 | B206: 7.4 | C206: 4.58 | D206: -4.3 | E206: 7.1
A207: 2024 | B207: 2.5 | C207: 5.12 | D207: -1.4 | E207: 5.3
A208: 2025 | B208: 3.4 | C208: 4.31 | D208: -1 | E208: 4.8
A209: 2026 | B209: 3 | C209: 3.75 | D209: 1.1 | E209: 4.1
A211: Year | B211: All Retail | C211: Food | D211: Non-Food | E211: Clothing | F211: HH Goods | G211: Non-Store
A212: 2018 | B212: 100.8 | C212: 103.3 | D212: 104.1 | E212: 100.5 | F212: 114.3 | G212: 78.3
A213: 2019 | B213: 103.9 | C213: 104.6 | D213: 105.4 | E213: 103 | F213: 111 | G213: 89.5
A214: 2020 | B214: 102.4 | C214: 109.5 | D214: 92.9 | E214: 76.4 | F214: 110.3 | G214: 119.8
A215: 2021 | B215: 107.5 | C215: 109.9 | D215: 101.9 | E215: 88.3 | F215: 117.8 | G215: 121.6
A216: 2022 | B216: 103.3 | C216: 103.4 | D216: 103.1 | E216: 99.5 | F216: 105.6 | G216: 103.3
A217: 2023 | B217: 100.1 | C217: 100.1 | D217: 100.1 | E217: 100.1 | F217: 100 | G217: 100.1
A218: 2024 | B218: 100.2 | C218: 98.5 | D218: 100.7 | E218: 96 | F218: 96.5 | G218: 102.2
A219: 2025 | B219: 101.5 | C219: 99 | D219: 102.9 | E219: 98.4 | F219: 99.9 | G219: 106.1
A220: 2026 | B220: 102.9 | C220: 98.9 | D220: 105.8 | E220: 100.1 | F220: 101.3 | G220: 110.9
A222: Date | B222: BoE Rate% | C222: RSI Nom YoY% | D222: Real RSI%
A223: 2018-01 | B223: 0.5 | C223: 4.6 | D223: 1.6
...
